2025-08-17 19:55:18 Logging attempt 2 to ./logs/run_20250817_195518_attempt_2.log
2025-08-17 19:55:18 Starting (attempt 2) â†’ python -m src.main -c llama_mask_cpu
Loaded environment variables from /home/riya/pivotal/pivotal-research/evaluating-probes/.env

=== DEBUG: Environment Variables ===
OPENAI_API_KEY=sk**************************************************************************************************************************************************************VwIA
OMP_NUM_THREADS=1
CUDA_VISIBLE_DEVICES=None
EP_BATCHED_NJOBS=32
====================================

Set CUDA_VISIBLE_DEVICES to 1, updated device to cuda:0

=== DEBUG: Environment Variables ===
OPENAI_API_KEY=sk**************************************************************************************************************************************************************VwIA
OMP_NUM_THREADS=1
CUDA_VISIBLE_DEVICES=1
EP_BATCHED_NJOBS=32
====================================

[model_check] Clearing CUDA memory at start...
Updated device from cuda:1 to cuda:0
Processing 10 seeds: [42, 43, 44, 45, 46, 47, 48, 49, 50, 51]
No llm_upsampling_experiments found, skipping LLM upsampling
Loading model 'meta-llama/Llama-3.3-70B-Instruct' for activation extraction...
================================================================================
ðŸ˜œ Run finished. Closing log file.
Traceback (most recent call last):
  File "/home/riya/2025_env/lib/python3.12/site-packages/huggingface_hub/utils/_http.py", line 409, in hf_raise_for_status
    response.raise_for_status()
  File "/home/riya/2025_env/lib/python3.12/site-packages/requests/models.py", line 1024, in raise_for_status
    raise HTTPError(http_error_msg, response=self)
requests.exceptions.HTTPError: 403 Client Error: Forbidden for url: https://huggingface.co/meta-llama/Llama-3.3-70B-Instruct/resolve/main/config.json

The above exception was the direct cause of the following exception:

Traceback (most recent call last):
  File "/home/riya/2025_env/lib/python3.12/site-packages/transformers/utils/hub.py", line 470, in cached_files
    hf_hub_download(
  File "/home/riya/2025_env/lib/python3.12/site-packages/huggingface_hub/utils/_validators.py", line 114, in _inner_fn
    return fn(*args, **kwargs)
           ^^^^^^^^^^^^^^^^^^^
  File "/home/riya/2025_env/lib/python3.12/site-packages/huggingface_hub/file_download.py", line 961, in hf_hub_download
    return _hf_hub_download_to_cache_dir(
           ^^^^^^^^^^^^^^^^^^^^^^^^^^^^^^
  File "/home/riya/2025_env/lib/python3.12/site-packages/huggingface_hub/file_download.py", line 1068, in _hf_hub_download_to_cache_dir
    _raise_on_head_call_error(head_call_error, force_download, local_files_only)
  File "/home/riya/2025_env/lib/python3.12/site-packages/huggingface_hub/file_download.py", line 1596, in _raise_on_head_call_error
    raise head_call_error
  File "/home/riya/2025_env/lib/python3.12/site-packages/huggingface_hub/file_download.py", line 1484, in _get_metadata_or_catch_error
    metadata = get_hf_file_metadata(
               ^^^^^^^^^^^^^^^^^^^^^
  File "/home/riya/2025_env/lib/python3.12/site-packages/huggingface_hub/utils/_validators.py", line 114, in _inner_fn
    return fn(*args, **kwargs)
           ^^^^^^^^^^^^^^^^^^^
  File "/home/riya/2025_env/lib/python3.12/site-packages/huggingface_hub/file_download.py", line 1401, in get_hf_file_metadata
    r = _request_wrapper(
        ^^^^^^^^^^^^^^^^^
  File "/home/riya/2025_env/lib/python3.12/site-packages/huggingface_hub/file_download.py", line 285, in _request_wrapper
    response = _request_wrapper(
               ^^^^^^^^^^^^^^^^^
  File "/home/riya/2025_env/lib/python3.12/site-packages/huggingface_hub/file_download.py", line 309, in _request_wrapper
    hf_raise_for_status(response)
  File "/home/riya/2025_env/lib/python3.12/site-packages/huggingface_hub/utils/_http.py", line 426, in hf_raise_for_status
    raise _format(GatedRepoError, message, response) from e
huggingface_hub.errors.GatedRepoError: 403 Client Error. (Request ID: Root=1-68a233aa-6a7c2a00502f5a2557b82fc9;bc175ec8-6379-4174-8a74-e01346b05759)

Cannot access gated repo for url https://huggingface.co/meta-llama/Llama-3.3-70B-Instruct/resolve/main/config.json.
Access to model meta-llama/Llama-3.3-70B-Instruct is restricted and you are not in the authorized list. Visit https://huggingface.co/meta-llama/Llama-3.3-70B-Instruct to ask for access.

The above exception was the direct cause of the following exception:

Traceback (most recent call last):
  File "<frozen runpy>", line 198, in _run_module_as_main
  File "<frozen runpy>", line 88, in _run_code
  File "/home/riya/pivotal/pivotal-research/evaluating-probes/src/main.py", line 1002, in <module>
    main()
  File "/home/riya/pivotal/pivotal-research/evaluating-probes/src/main.py", line 938, in main
    model = AutoModelForCausalLM.from_pretrained(
            ^^^^^^^^^^^^^^^^^^^^^^^^^^^^^^^^^^^^^
  File "/home/riya/2025_env/lib/python3.12/site-packages/transformers/models/auto/auto_factory.py", line 531, in from_pretrained
    config, kwargs = AutoConfig.from_pretrained(
                     ^^^^^^^^^^^^^^^^^^^^^^^^^^^
  File "/home/riya/2025_env/lib/python3.12/site-packages/transformers/models/auto/configuration_auto.py", line 1149, in from_pretrained
    config_dict, unused_kwargs = PretrainedConfig.get_config_dict(pretrained_model_name_or_path, **kwargs)
                                 ^^^^^^^^^^^^^^^^^^^^^^^^^^^^^^^^^^^^^^^^^^^^^^^^^^^^^^^^^^^^^^^^^^^^^^^^^
  File "/home/riya/2025_env/lib/python3.12/site-packages/transformers/configuration_utils.py", line 591, in get_config_dict
    config_dict, kwargs = cls._get_config_dict(pretrained_model_name_or_path, **kwargs)
                          ^^^^^^^^^^^^^^^^^^^^^^^^^^^^^^^^^^^^^^^^^^^^^^^^^^^^^^^^^^^^^
  File "/home/riya/2025_env/lib/python3.12/site-packages/transformers/configuration_utils.py", line 650, in _get_config_dict
    resolved_config_file = cached_file(
                           ^^^^^^^^^^^^
  File "/home/riya/2025_env/lib/python3.12/site-packages/transformers/utils/hub.py", line 312, in cached_file
    file = cached_files(path_or_repo_id=path_or_repo_id, filenames=[filename], **kwargs)
           ^^^^^^^^^^^^^^^^^^^^^^^^^^^^^^^^^^^^^^^^^^^^^^^^^^^^^^^^^^^^^^^^^^^^^^^^^^^^^
  File "/home/riya/2025_env/lib/python3.12/site-packages/transformers/utils/hub.py", line 533, in cached_files
    raise OSError(
OSError: You are trying to access a gated repo.
Make sure to have access to it at https://huggingface.co/meta-llama/Llama-3.3-70B-Instruct.
403 Client Error. (Request ID: Root=1-68a233aa-6a7c2a00502f5a2557b82fc9;bc175ec8-6379-4174-8a74-e01346b05759)

Cannot access gated repo for url https://huggingface.co/meta-llama/Llama-3.3-70B-Instruct/resolve/main/config.json.
Access to model meta-llama/Llama-3.3-70B-Instruct is restricted and you are not in the authorized list. Visit https://huggingface.co/meta-llama/Llama-3.3-70B-Instruct to ask for access.
2025-08-17 19:55:22 Command exited with status 1. Will restart.
2025-08-17 19:55:22 Sleeping 1s before restart #2...
